19-Jun-25 09:56:16 - INFO - server.py - Started server process [18756]
19-Jun-25 09:56:16 - INFO - on.py - Waiting for application startup.
19-Jun-25 09:56:16 - INFO - on.py - Application startup complete.
19-Jun-25 09:56:21 - INFO - httptools_impl.py - 127.0.0.1:57457 - "GET /audit/audit-tables HTTP/1.1" 404
19-Jun-25 09:56:43 - INFO - server.py - Shutting down
19-Jun-25 09:56:43 - INFO - on.py - Waiting for application shutdown.
19-Jun-25 09:56:43 - INFO - on.py - Application shutdown complete.
19-Jun-25 09:56:43 - INFO - server.py - Finished server process [18756]
19-Jun-25 09:56:46 - INFO - server.py - Started server process [13808]
19-Jun-25 09:56:46 - INFO - on.py - Waiting for application startup.
19-Jun-25 09:56:46 - INFO - on.py - Application startup complete.
19-Jun-25 09:56:46 - INFO - httptools_impl.py - 127.0.0.1:57505 - "GET /audit/audit-tables HTTP/1.1" 200
19-Jun-25 09:57:01 - INFO - httptools_impl.py - 127.0.0.1:57534 - "GET /audit/audit-fields HTTP/1.1" 200
19-Jun-25 09:57:13 - INFO - httptools_impl.py - 127.0.0.1:57553 - "GET /audit/audit-fields HTTP/1.1" 200
19-Jun-25 09:57:17 - INFO - httptools_impl.py - 127.0.0.1:57553 - "GET /audit/audit-tables HTTP/1.1" 200
19-Jun-25 09:57:20 - INFO - httptools_impl.py - 127.0.0.1:57553 - "GET /audit/audit-tables HTTP/1.1" 200
19-Jun-25 09:57:30 - INFO - httptools_impl.py - 127.0.0.1:57578 - "GET /audit/audit-fields HTTP/1.1" 200
19-Jun-25 09:57:41 - INFO - httptools_impl.py - 127.0.0.1:57593 - "POST /audit/add-audit HTTP/1.1" 500
19-Jun-25 09:57:41 - ERROR - httptools_impl.py - Exception in ASGI application
  + Exception Group Traceback (most recent call last):
  |   File "C:\Users\SINCHAS\AppData\Local\Programs\Python\Python312\Lib\site-packages\uvicorn\protocols\http\httptools_impl.py", line 435, in run_asgi
  |     result = await app(  # type: ignore[func-returns-value]
  |              ^^^^^^^^^^^^^^^^^^^^^^^^^^^^^^^^^^^^^^^^^^^^^^
  |   File "C:\Users\SINCHAS\AppData\Local\Programs\Python\Python312\Lib\site-packages\uvicorn\middleware\proxy_headers.py", line 78, in __call__
  |     return await self.app(scope, receive, send)
  |            ^^^^^^^^^^^^^^^^^^^^^^^^^^^^^^^^^^^^
  |   File "C:\Users\SINCHAS\AppData\Local\Programs\Python\Python312\Lib\site-packages\uvicorn\middleware\message_logger.py", line 86, in __call__
  |     raise exc from None
  |   File "C:\Users\SINCHAS\AppData\Local\Programs\Python\Python312\Lib\site-packages\uvicorn\middleware\message_logger.py", line 82, in __call__
  |     await self.app(scope, inner_receive, inner_send)
  |   File "C:\Users\SINCHAS\AppData\Local\Programs\Python\Python312\Lib\site-packages\fastapi\applications.py", line 276, in __call__
  |     await super().__call__(scope, receive, send)
  |   File "C:\Users\SINCHAS\AppData\Local\Programs\Python\Python312\Lib\site-packages\starlette\applications.py", line 122, in __call__
  |     await self.middleware_stack(scope, receive, send)
  |   File "C:\Users\SINCHAS\AppData\Local\Programs\Python\Python312\Lib\site-packages\starlette\middleware\errors.py", line 184, in __call__
  |     raise exc
  |   File "C:\Users\SINCHAS\AppData\Local\Programs\Python\Python312\Lib\site-packages\starlette\middleware\errors.py", line 162, in __call__
  |     await self.app(scope, receive, _send)
  |   File "C:\Users\SINCHAS\AppData\Local\Programs\Python\Python312\Lib\site-packages\starlette\middleware\cors.py", line 84, in __call__
  |     await self.app(scope, receive, send)
  |   File "C:\Users\SINCHAS\AppData\Local\Programs\Python\Python312\Lib\site-packages\starlette\middleware\base.py", line 106, in __call__
  |     async with anyio.create_task_group() as task_group:
  |   File "C:\Users\SINCHAS\AppData\Local\Programs\Python\Python312\Lib\site-packages\anyio\_backends\_asyncio.py", line 678, in __aexit__
  |     raise BaseExceptionGroup(
  | ExceptionGroup: unhandled errors in a TaskGroup (1 sub-exception)
  +-+---------------- 1 ----------------
    | Traceback (most recent call last):
    |   File "C:\Users\SINCHAS\AppData\Local\Programs\Python\Python312\Lib\site-packages\anyio\streams\memory.py", line 97, in receive
    |     return self.receive_nowait()
    |            ^^^^^^^^^^^^^^^^^^^^^
    |   File "C:\Users\SINCHAS\AppData\Local\Programs\Python\Python312\Lib\site-packages\anyio\streams\memory.py", line 92, in receive_nowait
    |     raise WouldBlock
    | anyio.WouldBlock
    | 
    | During handling of the above exception, another exception occurred:
    | 
    | Traceback (most recent call last):
    |   File "C:\Users\SINCHAS\AppData\Local\Programs\Python\Python312\Lib\site-packages\starlette\middleware\base.py", line 78, in call_next
    |     message = await recv_stream.receive()
    |               ^^^^^^^^^^^^^^^^^^^^^^^^^^^
    |   File "C:\Users\SINCHAS\AppData\Local\Programs\Python\Python312\Lib\site-packages\anyio\streams\memory.py", line 112, in receive
    |     raise EndOfStream
    | anyio.EndOfStream
    | 
    | During handling of the above exception, another exception occurred:
    | 
    | Traceback (most recent call last):
    |   File "C:\Users\SINCHAS\AppData\Local\Programs\Python\Python312\Lib\site-packages\starlette\middleware\base.py", line 108, in __call__
    |     response = await self.dispatch_func(request, call_next)
    |                ^^^^^^^^^^^^^^^^^^^^^^^^^^^^^^^^^^^^^^^^^^^^
    |   File "C:\Users\SINCHAS\Documents\GitHub\eProvision\backend\src\main.py", line 34, in dispatch
    |     response = await call_next(request)
    |                ^^^^^^^^^^^^^^^^^^^^^^^^
    |   File "C:\Users\SINCHAS\AppData\Local\Programs\Python\Python312\Lib\site-packages\starlette\middleware\base.py", line 84, in call_next
    |     raise app_exc
    |   File "C:\Users\SINCHAS\AppData\Local\Programs\Python\Python312\Lib\site-packages\starlette\middleware\base.py", line 70, in coro
    |     await self.app(scope, receive_or_disconnect, send_no_error)
    |   File "C:\Users\SINCHAS\AppData\Local\Programs\Python\Python312\Lib\site-packages\starlette\middleware\exceptions.py", line 79, in __call__
    |     raise exc
    |   File "C:\Users\SINCHAS\AppData\Local\Programs\Python\Python312\Lib\site-packages\starlette\middleware\exceptions.py", line 68, in __call__
    |     await self.app(scope, receive, sender)
    |   File "C:\Users\SINCHAS\AppData\Local\Programs\Python\Python312\Lib\site-packages\fastapi\middleware\asyncexitstack.py", line 21, in __call__
    |     raise e
    |   File "C:\Users\SINCHAS\AppData\Local\Programs\Python\Python312\Lib\site-packages\fastapi\middleware\asyncexitstack.py", line 18, in __call__
    |     await self.app(scope, receive, send)
    |   File "C:\Users\SINCHAS\AppData\Local\Programs\Python\Python312\Lib\site-packages\starlette\routing.py", line 718, in __call__
    |     await route.handle(scope, receive, send)
    |   File "C:\Users\SINCHAS\AppData\Local\Programs\Python\Python312\Lib\site-packages\starlette\routing.py", line 276, in handle
    |     await self.app(scope, receive, send)
    |   File "C:\Users\SINCHAS\AppData\Local\Programs\Python\Python312\Lib\site-packages\starlette\routing.py", line 66, in app
    |     response = await func(request)
    |                ^^^^^^^^^^^^^^^^^^^
    |   File "C:\Users\SINCHAS\AppData\Local\Programs\Python\Python312\Lib\site-packages\fastapi\routing.py", line 237, in app
    |     raw_response = await run_endpoint_function(
    |                    ^^^^^^^^^^^^^^^^^^^^^^^^^^^^
    |   File "C:\Users\SINCHAS\AppData\Local\Programs\Python\Python312\Lib\site-packages\fastapi\routing.py", line 163, in run_endpoint_function
    |     return await dependant.call(**values)
    |            ^^^^^^^^^^^^^^^^^^^^^^^^^^^^^^
    |   File "C:\Users\SINCHAS\Documents\GitHub\eProvision\backend\src\routers\audit_setup.py", line 21, in add_audit_table
    |     return add_table(request.headers,tabledetails, db)
    |            ^^^^^^^^^^^^^^^^^^^^^^^^^^^^^^^^^^^^^^^^^^^
    |   File "C:\Users\SINCHAS\Documents\GitHub\eProvision\backend\src\modules\audit_setup\audit_setup.py", line 182, in add_table
    |     token = token.split()[1]
    |             ^^^^^^^^^^^
    | AttributeError: 'NoneType' object has no attribute 'split'
    +------------------------------------
19-Jun-25 09:58:58 - INFO - httptools_impl.py - 127.0.0.1:57687 - "POST /audit/add-audit HTTP/1.1" 500
19-Jun-25 09:58:58 - ERROR - httptools_impl.py - Exception in ASGI application
  + Exception Group Traceback (most recent call last):
  |   File "C:\Users\SINCHAS\AppData\Local\Programs\Python\Python312\Lib\site-packages\uvicorn\protocols\http\httptools_impl.py", line 435, in run_asgi
  |     result = await app(  # type: ignore[func-returns-value]
  |              ^^^^^^^^^^^^^^^^^^^^^^^^^^^^^^^^^^^^^^^^^^^^^^
  |   File "C:\Users\SINCHAS\AppData\Local\Programs\Python\Python312\Lib\site-packages\uvicorn\middleware\proxy_headers.py", line 78, in __call__
  |     return await self.app(scope, receive, send)
  |            ^^^^^^^^^^^^^^^^^^^^^^^^^^^^^^^^^^^^
  |   File "C:\Users\SINCHAS\AppData\Local\Programs\Python\Python312\Lib\site-packages\uvicorn\middleware\message_logger.py", line 86, in __call__
  |     raise exc from None
  |   File "C:\Users\SINCHAS\AppData\Local\Programs\Python\Python312\Lib\site-packages\uvicorn\middleware\message_logger.py", line 82, in __call__
  |     await self.app(scope, inner_receive, inner_send)
  |   File "C:\Users\SINCHAS\AppData\Local\Programs\Python\Python312\Lib\site-packages\fastapi\applications.py", line 276, in __call__
  |     await super().__call__(scope, receive, send)
  |   File "C:\Users\SINCHAS\AppData\Local\Programs\Python\Python312\Lib\site-packages\starlette\applications.py", line 122, in __call__
  |     await self.middleware_stack(scope, receive, send)
  |   File "C:\Users\SINCHAS\AppData\Local\Programs\Python\Python312\Lib\site-packages\starlette\middleware\errors.py", line 184, in __call__
  |     raise exc
  |   File "C:\Users\SINCHAS\AppData\Local\Programs\Python\Python312\Lib\site-packages\starlette\middleware\errors.py", line 162, in __call__
  |     await self.app(scope, receive, _send)
  |   File "C:\Users\SINCHAS\AppData\Local\Programs\Python\Python312\Lib\site-packages\starlette\middleware\cors.py", line 84, in __call__
  |     await self.app(scope, receive, send)
  |   File "C:\Users\SINCHAS\AppData\Local\Programs\Python\Python312\Lib\site-packages\starlette\middleware\base.py", line 106, in __call__
  |     async with anyio.create_task_group() as task_group:
  |   File "C:\Users\SINCHAS\AppData\Local\Programs\Python\Python312\Lib\site-packages\anyio\_backends\_asyncio.py", line 678, in __aexit__
  |     raise BaseExceptionGroup(
  | ExceptionGroup: unhandled errors in a TaskGroup (1 sub-exception)
  +-+---------------- 1 ----------------
    | Traceback (most recent call last):
    |   File "C:\Users\SINCHAS\AppData\Local\Programs\Python\Python312\Lib\site-packages\anyio\streams\memory.py", line 97, in receive
    |     return self.receive_nowait()
    |            ^^^^^^^^^^^^^^^^^^^^^
    |   File "C:\Users\SINCHAS\AppData\Local\Programs\Python\Python312\Lib\site-packages\anyio\streams\memory.py", line 92, in receive_nowait
    |     raise WouldBlock
    | anyio.WouldBlock
    | 
    | During handling of the above exception, another exception occurred:
    | 
    | Traceback (most recent call last):
    |   File "C:\Users\SINCHAS\AppData\Local\Programs\Python\Python312\Lib\site-packages\starlette\middleware\base.py", line 78, in call_next
    |     message = await recv_stream.receive()
    |               ^^^^^^^^^^^^^^^^^^^^^^^^^^^
    |   File "C:\Users\SINCHAS\AppData\Local\Programs\Python\Python312\Lib\site-packages\anyio\streams\memory.py", line 112, in receive
    |     raise EndOfStream
    | anyio.EndOfStream
    | 
    | During handling of the above exception, another exception occurred:
    | 
    | Traceback (most recent call last):
    |   File "C:\Users\SINCHAS\AppData\Local\Programs\Python\Python312\Lib\site-packages\starlette\middleware\base.py", line 108, in __call__
    |     response = await self.dispatch_func(request, call_next)
    |                ^^^^^^^^^^^^^^^^^^^^^^^^^^^^^^^^^^^^^^^^^^^^
    |   File "C:\Users\SINCHAS\Documents\GitHub\eProvision\backend\src\main.py", line 34, in dispatch
    |     response = await call_next(request)
    |                ^^^^^^^^^^^^^^^^^^^^^^^^
    |   File "C:\Users\SINCHAS\AppData\Local\Programs\Python\Python312\Lib\site-packages\starlette\middleware\base.py", line 84, in call_next
    |     raise app_exc
    |   File "C:\Users\SINCHAS\AppData\Local\Programs\Python\Python312\Lib\site-packages\starlette\middleware\base.py", line 70, in coro
    |     await self.app(scope, receive_or_disconnect, send_no_error)
    |   File "C:\Users\SINCHAS\AppData\Local\Programs\Python\Python312\Lib\site-packages\starlette\middleware\exceptions.py", line 79, in __call__
    |     raise exc
    |   File "C:\Users\SINCHAS\AppData\Local\Programs\Python\Python312\Lib\site-packages\starlette\middleware\exceptions.py", line 68, in __call__
    |     await self.app(scope, receive, sender)
    |   File "C:\Users\SINCHAS\AppData\Local\Programs\Python\Python312\Lib\site-packages\fastapi\middleware\asyncexitstack.py", line 21, in __call__
    |     raise e
    |   File "C:\Users\SINCHAS\AppData\Local\Programs\Python\Python312\Lib\site-packages\fastapi\middleware\asyncexitstack.py", line 18, in __call__
    |     await self.app(scope, receive, send)
    |   File "C:\Users\SINCHAS\AppData\Local\Programs\Python\Python312\Lib\site-packages\starlette\routing.py", line 718, in __call__
    |     await route.handle(scope, receive, send)
    |   File "C:\Users\SINCHAS\AppData\Local\Programs\Python\Python312\Lib\site-packages\starlette\routing.py", line 276, in handle
    |     await self.app(scope, receive, send)
    |   File "C:\Users\SINCHAS\AppData\Local\Programs\Python\Python312\Lib\site-packages\starlette\routing.py", line 66, in app
    |     response = await func(request)
    |                ^^^^^^^^^^^^^^^^^^^
    |   File "C:\Users\SINCHAS\AppData\Local\Programs\Python\Python312\Lib\site-packages\fastapi\routing.py", line 237, in app
    |     raw_response = await run_endpoint_function(
    |                    ^^^^^^^^^^^^^^^^^^^^^^^^^^^^
    |   File "C:\Users\SINCHAS\AppData\Local\Programs\Python\Python312\Lib\site-packages\fastapi\routing.py", line 163, in run_endpoint_function
    |     return await dependant.call(**values)
    |            ^^^^^^^^^^^^^^^^^^^^^^^^^^^^^^
    |   File "C:\Users\SINCHAS\Documents\GitHub\eProvision\backend\src\routers\audit_setup.py", line 21, in add_audit_table
    |     return add_table(request.headers,tabledetails, db)
    |            ^^^^^^^^^^^^^^^^^^^^^^^^^^^^^^^^^^^^^^^^^^^
    |   File "C:\Users\SINCHAS\Documents\GitHub\eProvision\backend\src\modules\audit_setup\audit_setup.py", line 182, in add_table
    |     token = token.split()[1]
    |             ^^^^^^^^^^^
    | AttributeError: 'NoneType' object has no attribute 'split'
    +------------------------------------
19-Jun-25 09:59:16 - INFO - server.py - Shutting down
19-Jun-25 09:59:16 - INFO - on.py - Waiting for application shutdown.
19-Jun-25 09:59:16 - INFO - on.py - Application shutdown complete.
19-Jun-25 09:59:16 - INFO - server.py - Finished server process [13808]
19-Jun-25 09:59:25 - INFO - server.py - Started server process [24556]
19-Jun-25 09:59:25 - INFO - on.py - Waiting for application startup.
19-Jun-25 09:59:25 - INFO - on.py - Application startup complete.
19-Jun-25 09:59:25 - INFO - httptools_impl.py - 127.0.0.1:57716 - "POST /audit/add-audit HTTP/1.1" 500
19-Jun-25 09:59:25 - ERROR - httptools_impl.py - Exception in ASGI application
  + Exception Group Traceback (most recent call last):
  |   File "C:\Users\SINCHAS\AppData\Local\Programs\Python\Python312\Lib\site-packages\uvicorn\protocols\http\httptools_impl.py", line 435, in run_asgi
  |     result = await app(  # type: ignore[func-returns-value]
  |              ^^^^^^^^^^^^^^^^^^^^^^^^^^^^^^^^^^^^^^^^^^^^^^
  |   File "C:\Users\SINCHAS\AppData\Local\Programs\Python\Python312\Lib\site-packages\uvicorn\middleware\proxy_headers.py", line 78, in __call__
  |     return await self.app(scope, receive, send)
  |            ^^^^^^^^^^^^^^^^^^^^^^^^^^^^^^^^^^^^
  |   File "C:\Users\SINCHAS\AppData\Local\Programs\Python\Python312\Lib\site-packages\uvicorn\middleware\message_logger.py", line 86, in __call__
  |     raise exc from None
  |   File "C:\Users\SINCHAS\AppData\Local\Programs\Python\Python312\Lib\site-packages\uvicorn\middleware\message_logger.py", line 82, in __call__
  |     await self.app(scope, inner_receive, inner_send)
  |   File "C:\Users\SINCHAS\AppData\Local\Programs\Python\Python312\Lib\site-packages\fastapi\applications.py", line 276, in __call__
  |     await super().__call__(scope, receive, send)
  |   File "C:\Users\SINCHAS\AppData\Local\Programs\Python\Python312\Lib\site-packages\starlette\applications.py", line 122, in __call__
  |     await self.middleware_stack(scope, receive, send)
  |   File "C:\Users\SINCHAS\AppData\Local\Programs\Python\Python312\Lib\site-packages\starlette\middleware\errors.py", line 184, in __call__
  |     raise exc
  |   File "C:\Users\SINCHAS\AppData\Local\Programs\Python\Python312\Lib\site-packages\starlette\middleware\errors.py", line 162, in __call__
  |     await self.app(scope, receive, _send)
  |   File "C:\Users\SINCHAS\AppData\Local\Programs\Python\Python312\Lib\site-packages\starlette\middleware\cors.py", line 84, in __call__
  |     await self.app(scope, receive, send)
  |   File "C:\Users\SINCHAS\AppData\Local\Programs\Python\Python312\Lib\site-packages\starlette\middleware\base.py", line 106, in __call__
  |     async with anyio.create_task_group() as task_group:
  |   File "C:\Users\SINCHAS\AppData\Local\Programs\Python\Python312\Lib\site-packages\anyio\_backends\_asyncio.py", line 678, in __aexit__
  |     raise BaseExceptionGroup(
  | ExceptionGroup: unhandled errors in a TaskGroup (1 sub-exception)
  +-+---------------- 1 ----------------
    | Traceback (most recent call last):
    |   File "C:\Users\SINCHAS\AppData\Local\Programs\Python\Python312\Lib\site-packages\anyio\streams\memory.py", line 97, in receive
    |     return self.receive_nowait()
    |            ^^^^^^^^^^^^^^^^^^^^^
    |   File "C:\Users\SINCHAS\AppData\Local\Programs\Python\Python312\Lib\site-packages\anyio\streams\memory.py", line 92, in receive_nowait
    |     raise WouldBlock
    | anyio.WouldBlock
    | 
    | During handling of the above exception, another exception occurred:
    | 
    | Traceback (most recent call last):
    |   File "C:\Users\SINCHAS\AppData\Local\Programs\Python\Python312\Lib\site-packages\starlette\middleware\base.py", line 78, in call_next
    |     message = await recv_stream.receive()
    |               ^^^^^^^^^^^^^^^^^^^^^^^^^^^
    |   File "C:\Users\SINCHAS\AppData\Local\Programs\Python\Python312\Lib\site-packages\anyio\streams\memory.py", line 112, in receive
    |     raise EndOfStream
    | anyio.EndOfStream
    | 
    | During handling of the above exception, another exception occurred:
    | 
    | Traceback (most recent call last):
    |   File "C:\Users\SINCHAS\AppData\Local\Programs\Python\Python312\Lib\site-packages\starlette\middleware\base.py", line 108, in __call__
    |     response = await self.dispatch_func(request, call_next)
    |                ^^^^^^^^^^^^^^^^^^^^^^^^^^^^^^^^^^^^^^^^^^^^
    |   File "C:\Users\SINCHAS\Documents\GitHub\eProvision\backend\src\main.py", line 34, in dispatch
    |     response = await call_next(request)
    |                ^^^^^^^^^^^^^^^^^^^^^^^^
    |   File "C:\Users\SINCHAS\AppData\Local\Programs\Python\Python312\Lib\site-packages\starlette\middleware\base.py", line 84, in call_next
    |     raise app_exc
    |   File "C:\Users\SINCHAS\AppData\Local\Programs\Python\Python312\Lib\site-packages\starlette\middleware\base.py", line 70, in coro
    |     await self.app(scope, receive_or_disconnect, send_no_error)
    |   File "C:\Users\SINCHAS\AppData\Local\Programs\Python\Python312\Lib\site-packages\starlette\middleware\exceptions.py", line 79, in __call__
    |     raise exc
    |   File "C:\Users\SINCHAS\AppData\Local\Programs\Python\Python312\Lib\site-packages\starlette\middleware\exceptions.py", line 68, in __call__
    |     await self.app(scope, receive, sender)
    |   File "C:\Users\SINCHAS\AppData\Local\Programs\Python\Python312\Lib\site-packages\fastapi\middleware\asyncexitstack.py", line 21, in __call__
    |     raise e
    |   File "C:\Users\SINCHAS\AppData\Local\Programs\Python\Python312\Lib\site-packages\fastapi\middleware\asyncexitstack.py", line 18, in __call__
    |     await self.app(scope, receive, send)
    |   File "C:\Users\SINCHAS\AppData\Local\Programs\Python\Python312\Lib\site-packages\starlette\routing.py", line 718, in __call__
    |     await route.handle(scope, receive, send)
    |   File "C:\Users\SINCHAS\AppData\Local\Programs\Python\Python312\Lib\site-packages\starlette\routing.py", line 276, in handle
    |     await self.app(scope, receive, send)
    |   File "C:\Users\SINCHAS\AppData\Local\Programs\Python\Python312\Lib\site-packages\starlette\routing.py", line 66, in app
    |     response = await func(request)
    |                ^^^^^^^^^^^^^^^^^^^
    |   File "C:\Users\SINCHAS\AppData\Local\Programs\Python\Python312\Lib\site-packages\fastapi\routing.py", line 237, in app
    |     raw_response = await run_endpoint_function(
    |                    ^^^^^^^^^^^^^^^^^^^^^^^^^^^^
    |   File "C:\Users\SINCHAS\AppData\Local\Programs\Python\Python312\Lib\site-packages\fastapi\routing.py", line 163, in run_endpoint_function
    |     return await dependant.call(**values)
    |            ^^^^^^^^^^^^^^^^^^^^^^^^^^^^^^
    |   File "C:\Users\SINCHAS\Documents\GitHub\eProvision\backend\src\routers\audit_setup.py", line 21, in add_audit_table
    |     return add_table(request.headers,tabledetails, db)
    |            ^^^^^^^^^^^^^^^^^^^^^^^^^^^^^^^^^^^^^^^^^^^
    |   File "C:\Users\SINCHAS\Documents\GitHub\eProvision\backend\src\modules\audit_setup\audit_setup.py", line 182, in add_table
    |     token = token.split()[1]
    |             ^^^^^^^^^^^
    | AttributeError: 'NoneType' object has no attribute 'split'
    +------------------------------------
19-Jun-25 09:59:30 - INFO - server.py - Shutting down
19-Jun-25 09:59:30 - INFO - on.py - Waiting for application shutdown.
19-Jun-25 09:59:30 - INFO - on.py - Application shutdown complete.
19-Jun-25 09:59:30 - INFO - server.py - Finished server process [24556]
19-Jun-25 09:59:33 - INFO - server.py - Started server process [25752]
19-Jun-25 09:59:33 - INFO - on.py - Waiting for application startup.
19-Jun-25 09:59:33 - INFO - on.py - Application startup complete.
19-Jun-25 09:59:34 - INFO - httptools_impl.py - 127.0.0.1:57740 - "POST /audit/add-audit HTTP/1.1" 500
19-Jun-25 09:59:34 - ERROR - httptools_impl.py - Exception in ASGI application
  + Exception Group Traceback (most recent call last):
  |   File "C:\Users\SINCHAS\AppData\Local\Programs\Python\Python312\Lib\site-packages\uvicorn\protocols\http\httptools_impl.py", line 435, in run_asgi
  |     result = await app(  # type: ignore[func-returns-value]
  |              ^^^^^^^^^^^^^^^^^^^^^^^^^^^^^^^^^^^^^^^^^^^^^^
  |   File "C:\Users\SINCHAS\AppData\Local\Programs\Python\Python312\Lib\site-packages\uvicorn\middleware\proxy_headers.py", line 78, in __call__
  |     return await self.app(scope, receive, send)
  |            ^^^^^^^^^^^^^^^^^^^^^^^^^^^^^^^^^^^^
  |   File "C:\Users\SINCHAS\AppData\Local\Programs\Python\Python312\Lib\site-packages\uvicorn\middleware\message_logger.py", line 86, in __call__
  |     raise exc from None
  |   File "C:\Users\SINCHAS\AppData\Local\Programs\Python\Python312\Lib\site-packages\uvicorn\middleware\message_logger.py", line 82, in __call__
  |     await self.app(scope, inner_receive, inner_send)
  |   File "C:\Users\SINCHAS\AppData\Local\Programs\Python\Python312\Lib\site-packages\fastapi\applications.py", line 276, in __call__
  |     await super().__call__(scope, receive, send)
  |   File "C:\Users\SINCHAS\AppData\Local\Programs\Python\Python312\Lib\site-packages\starlette\applications.py", line 122, in __call__
  |     await self.middleware_stack(scope, receive, send)
  |   File "C:\Users\SINCHAS\AppData\Local\Programs\Python\Python312\Lib\site-packages\starlette\middleware\errors.py", line 184, in __call__
  |     raise exc
  |   File "C:\Users\SINCHAS\AppData\Local\Programs\Python\Python312\Lib\site-packages\starlette\middleware\errors.py", line 162, in __call__
  |     await self.app(scope, receive, _send)
  |   File "C:\Users\SINCHAS\AppData\Local\Programs\Python\Python312\Lib\site-packages\starlette\middleware\cors.py", line 84, in __call__
  |     await self.app(scope, receive, send)
  |   File "C:\Users\SINCHAS\AppData\Local\Programs\Python\Python312\Lib\site-packages\starlette\middleware\base.py", line 106, in __call__
  |     async with anyio.create_task_group() as task_group:
  |   File "C:\Users\SINCHAS\AppData\Local\Programs\Python\Python312\Lib\site-packages\anyio\_backends\_asyncio.py", line 678, in __aexit__
  |     raise BaseExceptionGroup(
  | ExceptionGroup: unhandled errors in a TaskGroup (1 sub-exception)
  +-+---------------- 1 ----------------
    | Traceback (most recent call last):
    |   File "C:\Users\SINCHAS\AppData\Local\Programs\Python\Python312\Lib\site-packages\anyio\streams\memory.py", line 97, in receive
    |     return self.receive_nowait()
    |            ^^^^^^^^^^^^^^^^^^^^^
    |   File "C:\Users\SINCHAS\AppData\Local\Programs\Python\Python312\Lib\site-packages\anyio\streams\memory.py", line 92, in receive_nowait
    |     raise WouldBlock
    | anyio.WouldBlock
    | 
    | During handling of the above exception, another exception occurred:
    | 
    | Traceback (most recent call last):
    |   File "C:\Users\SINCHAS\AppData\Local\Programs\Python\Python312\Lib\site-packages\starlette\middleware\base.py", line 78, in call_next
    |     message = await recv_stream.receive()
    |               ^^^^^^^^^^^^^^^^^^^^^^^^^^^
    |   File "C:\Users\SINCHAS\AppData\Local\Programs\Python\Python312\Lib\site-packages\anyio\streams\memory.py", line 112, in receive
    |     raise EndOfStream
    | anyio.EndOfStream
    | 
    | During handling of the above exception, another exception occurred:
    | 
    | Traceback (most recent call last):
    |   File "C:\Users\SINCHAS\AppData\Local\Programs\Python\Python312\Lib\site-packages\starlette\middleware\base.py", line 108, in __call__
    |     response = await self.dispatch_func(request, call_next)
    |                ^^^^^^^^^^^^^^^^^^^^^^^^^^^^^^^^^^^^^^^^^^^^
    |   File "C:\Users\SINCHAS\Documents\GitHub\eProvision\backend\src\main.py", line 34, in dispatch
    |     response = await call_next(request)
    |                ^^^^^^^^^^^^^^^^^^^^^^^^
    |   File "C:\Users\SINCHAS\AppData\Local\Programs\Python\Python312\Lib\site-packages\starlette\middleware\base.py", line 84, in call_next
    |     raise app_exc
    |   File "C:\Users\SINCHAS\AppData\Local\Programs\Python\Python312\Lib\site-packages\starlette\middleware\base.py", line 70, in coro
    |     await self.app(scope, receive_or_disconnect, send_no_error)
    |   File "C:\Users\SINCHAS\AppData\Local\Programs\Python\Python312\Lib\site-packages\starlette\middleware\exceptions.py", line 79, in __call__
    |     raise exc
    |   File "C:\Users\SINCHAS\AppData\Local\Programs\Python\Python312\Lib\site-packages\starlette\middleware\exceptions.py", line 68, in __call__
    |     await self.app(scope, receive, sender)
    |   File "C:\Users\SINCHAS\AppData\Local\Programs\Python\Python312\Lib\site-packages\fastapi\middleware\asyncexitstack.py", line 21, in __call__
    |     raise e
    |   File "C:\Users\SINCHAS\AppData\Local\Programs\Python\Python312\Lib\site-packages\fastapi\middleware\asyncexitstack.py", line 18, in __call__
    |     await self.app(scope, receive, send)
    |   File "C:\Users\SINCHAS\AppData\Local\Programs\Python\Python312\Lib\site-packages\starlette\routing.py", line 718, in __call__
    |     await route.handle(scope, receive, send)
    |   File "C:\Users\SINCHAS\AppData\Local\Programs\Python\Python312\Lib\site-packages\starlette\routing.py", line 276, in handle
    |     await self.app(scope, receive, send)
    |   File "C:\Users\SINCHAS\AppData\Local\Programs\Python\Python312\Lib\site-packages\starlette\routing.py", line 66, in app
    |     response = await func(request)
    |                ^^^^^^^^^^^^^^^^^^^
    |   File "C:\Users\SINCHAS\AppData\Local\Programs\Python\Python312\Lib\site-packages\fastapi\routing.py", line 237, in app
    |     raw_response = await run_endpoint_function(
    |                    ^^^^^^^^^^^^^^^^^^^^^^^^^^^^
    |   File "C:\Users\SINCHAS\AppData\Local\Programs\Python\Python312\Lib\site-packages\fastapi\routing.py", line 163, in run_endpoint_function
    |     return await dependant.call(**values)
    |            ^^^^^^^^^^^^^^^^^^^^^^^^^^^^^^
    |   File "C:\Users\SINCHAS\Documents\GitHub\eProvision\backend\src\routers\audit_setup.py", line 21, in add_audit_table
    |     return add_table(request.headers,tabledetails, db)
    |            ^^^^^^^^^^^^^^^^^^^^^^^^^^^^^^^^^^^^^^^^^^^
    |   File "C:\Users\SINCHAS\Documents\GitHub\eProvision\backend\src\modules\audit_setup\audit_setup.py", line 182, in add_table
    |     token = token.split()[1]
    |             ^^^^^^^^^^^
    | AttributeError: 'NoneType' object has no attribute 'split'
    +------------------------------------
19-Jun-25 09:59:49 - INFO - server.py - Shutting down
19-Jun-25 09:59:49 - INFO - on.py - Waiting for application shutdown.
19-Jun-25 09:59:49 - INFO - on.py - Application shutdown complete.
19-Jun-25 09:59:49 - INFO - server.py - Finished server process [25752]
19-Jun-25 09:59:52 - INFO - server.py - Started server process [31248]
19-Jun-25 09:59:52 - INFO - on.py - Waiting for application startup.
19-Jun-25 09:59:52 - INFO - on.py - Application startup complete.
19-Jun-25 09:59:58 - INFO - server.py - Shutting down
19-Jun-25 09:59:58 - INFO - on.py - Waiting for application shutdown.
19-Jun-25 09:59:58 - INFO - on.py - Application shutdown complete.
19-Jun-25 09:59:58 - INFO - server.py - Finished server process [31248]
19-Jun-25 10:00:25 - INFO - server.py - Started server process [29852]
19-Jun-25 10:00:25 - INFO - on.py - Waiting for application startup.
19-Jun-25 10:00:25 - INFO - on.py - Application startup complete.
19-Jun-25 10:00:32 - INFO - server.py - Shutting down
19-Jun-25 10:00:32 - INFO - on.py - Waiting for application shutdown.
19-Jun-25 10:00:32 - INFO - on.py - Application shutdown complete.
19-Jun-25 10:00:32 - INFO - server.py - Finished server process [29852]
19-Jun-25 10:00:35 - INFO - server.py - Started server process [27776]
19-Jun-25 10:00:35 - INFO - on.py - Waiting for application startup.
19-Jun-25 10:00:35 - INFO - on.py - Application startup complete.
19-Jun-25 10:00:38 - INFO - server.py - Shutting down
19-Jun-25 10:00:38 - INFO - on.py - Waiting for application shutdown.
19-Jun-25 10:00:38 - INFO - on.py - Application shutdown complete.
19-Jun-25 10:00:38 - INFO - server.py - Finished server process [27776]
19-Jun-25 10:00:41 - INFO - server.py - Started server process [26120]
19-Jun-25 10:00:41 - INFO - on.py - Waiting for application startup.
19-Jun-25 10:00:41 - INFO - on.py - Application startup complete.
19-Jun-25 10:00:45 - INFO - httptools_impl.py - 127.0.0.1:57867 - "POST /audit/add-audit HTTP/1.1" 200
19-Jun-25 10:00:51 - INFO - httptools_impl.py - 127.0.0.1:57875 - "GET /audit/audit-fields HTTP/1.1" 200
19-Jun-25 10:00:52 - INFO - httptools_impl.py - 127.0.0.1:57875 - "GET /audit/audit-fields HTTP/1.1" 200
19-Jun-25 10:00:53 - INFO - httptools_impl.py - 127.0.0.1:57875 - "GET /audit/audit-fields HTTP/1.1" 200
19-Jun-25 10:01:33 - INFO - httptools_impl.py - 127.0.0.1:57926 - "GET /audit/audit-tables HTTP/1.1" 200
19-Jun-25 10:02:32 - INFO - httptools_impl.py - 127.0.0.1:57989 - "GET /audit/audit-tables HTTP/1.1" 200
19-Jun-25 10:02:45 - INFO - httptools_impl.py - 127.0.0.1:58006 - "POST /audit/add-audit HTTP/1.1" 200
19-Jun-25 10:02:58 - INFO - httptools_impl.py - 127.0.0.1:58025 - "GET /audit/audit-fields HTTP/1.1" 200
19-Jun-25 10:05:13 - INFO - server.py - Shutting down
19-Jun-25 10:05:13 - INFO - on.py - Waiting for application shutdown.
19-Jun-25 10:05:13 - INFO - on.py - Application shutdown complete.
19-Jun-25 10:05:13 - INFO - server.py - Finished server process [26120]
19-Jun-25 10:05:16 - INFO - server.py - Started server process [29136]
19-Jun-25 10:05:16 - INFO - on.py - Waiting for application startup.
19-Jun-25 10:05:16 - ERROR - on.py - Traceback (most recent call last):
  File "C:\Users\SINCHAS\AppData\Local\Programs\Python\Python312\Lib\asyncio\runners.py", line 118, in run
    return self._loop.run_until_complete(task)
           ^^^^^^^^^^^^^^^^^^^^^^^^^^^^^^^^^^^
  File "C:\Users\SINCHAS\AppData\Local\Programs\Python\Python312\Lib\asyncio\base_events.py", line 687, in run_until_complete
    return future.result()
           ^^^^^^^^^^^^^^^
  File "C:\Users\SINCHAS\AppData\Local\Programs\Python\Python312\Lib\site-packages\uvicorn\server.py", line 78, in serve
    await self.startup(sockets=sockets)
  File "C:\Users\SINCHAS\AppData\Local\Programs\Python\Python312\Lib\site-packages\uvicorn\server.py", line 89, in startup
    await self.lifespan.startup()
  File "C:\Users\SINCHAS\AppData\Local\Programs\Python\Python312\Lib\site-packages\uvicorn\lifespan\on.py", line 56, in startup
    await self.startup_event.wait()
  File "C:\Users\SINCHAS\AppData\Local\Programs\Python\Python312\Lib\asyncio\locks.py", line 212, in wait
    await fut
asyncio.exceptions.CancelledError

During handling of the above exception, another exception occurred:

Traceback (most recent call last):
  File "C:\Users\SINCHAS\AppData\Local\Programs\Python\Python312\Lib\asyncio\runners.py", line 194, in run
    return runner.run(main)
           ^^^^^^^^^^^^^^^^
  File "C:\Users\SINCHAS\AppData\Local\Programs\Python\Python312\Lib\asyncio\runners.py", line 123, in run
    raise KeyboardInterrupt()
KeyboardInterrupt

During handling of the above exception, another exception occurred:

Traceback (most recent call last):
  File "C:\Users\SINCHAS\AppData\Local\Programs\Python\Python312\Lib\site-packages\starlette\routing.py", line 686, in lifespan
    await receive()
  File "C:\Users\SINCHAS\AppData\Local\Programs\Python\Python312\Lib\site-packages\uvicorn\middleware\message_logger.py", line 62, in inner_receive
    message = await receive()
              ^^^^^^^^^^^^^^^
  File "C:\Users\SINCHAS\AppData\Local\Programs\Python\Python312\Lib\site-packages\uvicorn\lifespan\on.py", line 139, in receive
    return await self.receive_queue.get()
           ^^^^^^^^^^^^^^^^^^^^^^^^^^^^^^
  File "C:\Users\SINCHAS\AppData\Local\Programs\Python\Python312\Lib\asyncio\queues.py", line 158, in get
    await getter
asyncio.exceptions.CancelledError

19-Jun-25 10:05:21 - INFO - server.py - Started server process [33352]
19-Jun-25 10:05:21 - INFO - on.py - Waiting for application startup.
19-Jun-25 10:05:21 - INFO - on.py - Application startup complete.
19-Jun-25 10:05:32 - INFO - server.py - Shutting down
19-Jun-25 10:05:33 - INFO - on.py - Waiting for application shutdown.
19-Jun-25 10:05:33 - INFO - on.py - Application shutdown complete.
19-Jun-25 10:05:33 - INFO - server.py - Finished server process [33352]
19-Jun-25 10:05:41 - INFO - server.py - Started server process [17368]
19-Jun-25 10:05:41 - INFO - on.py - Waiting for application startup.
19-Jun-25 10:05:41 - INFO - on.py - Application startup complete.
19-Jun-25 10:05:43 - INFO - server.py - Shutting down
19-Jun-25 10:05:44 - INFO - on.py - Waiting for application shutdown.
19-Jun-25 10:05:44 - INFO - on.py - Application shutdown complete.
19-Jun-25 10:05:44 - INFO - server.py - Finished server process [17368]
19-Jun-25 10:05:46 - INFO - server.py - Started server process [9688]
19-Jun-25 10:05:46 - INFO - on.py - Waiting for application startup.
19-Jun-25 10:05:46 - INFO - on.py - Application startup complete.
19-Jun-25 10:05:51 - INFO - server.py - Shutting down
19-Jun-25 10:05:51 - INFO - on.py - Waiting for application shutdown.
19-Jun-25 10:05:51 - INFO - on.py - Application shutdown complete.
19-Jun-25 10:05:51 - INFO - server.py - Finished server process [9688]
19-Jun-25 10:05:54 - INFO - server.py - Started server process [26976]
19-Jun-25 10:05:54 - INFO - on.py - Waiting for application startup.
19-Jun-25 10:05:54 - ERROR - on.py - Traceback (most recent call last):
  File "C:\Users\SINCHAS\AppData\Local\Programs\Python\Python312\Lib\asyncio\runners.py", line 118, in run
    return self._loop.run_until_complete(task)
           ^^^^^^^^^^^^^^^^^^^^^^^^^^^^^^^^^^^
  File "C:\Users\SINCHAS\AppData\Local\Programs\Python\Python312\Lib\asyncio\base_events.py", line 687, in run_until_complete
    return future.result()
           ^^^^^^^^^^^^^^^
  File "C:\Users\SINCHAS\AppData\Local\Programs\Python\Python312\Lib\site-packages\uvicorn\server.py", line 78, in serve
    await self.startup(sockets=sockets)
  File "C:\Users\SINCHAS\AppData\Local\Programs\Python\Python312\Lib\site-packages\uvicorn\server.py", line 89, in startup
    await self.lifespan.startup()
  File "C:\Users\SINCHAS\AppData\Local\Programs\Python\Python312\Lib\site-packages\uvicorn\lifespan\on.py", line 56, in startup
    await self.startup_event.wait()
  File "C:\Users\SINCHAS\AppData\Local\Programs\Python\Python312\Lib\asyncio\locks.py", line 212, in wait
    await fut
asyncio.exceptions.CancelledError

During handling of the above exception, another exception occurred:

Traceback (most recent call last):
  File "C:\Users\SINCHAS\AppData\Local\Programs\Python\Python312\Lib\asyncio\runners.py", line 194, in run
    return runner.run(main)
           ^^^^^^^^^^^^^^^^
  File "C:\Users\SINCHAS\AppData\Local\Programs\Python\Python312\Lib\asyncio\runners.py", line 123, in run
    raise KeyboardInterrupt()
KeyboardInterrupt

During handling of the above exception, another exception occurred:

Traceback (most recent call last):
  File "C:\Users\SINCHAS\AppData\Local\Programs\Python\Python312\Lib\site-packages\starlette\routing.py", line 686, in lifespan
    await receive()
  File "C:\Users\SINCHAS\AppData\Local\Programs\Python\Python312\Lib\site-packages\uvicorn\middleware\message_logger.py", line 62, in inner_receive
    message = await receive()
              ^^^^^^^^^^^^^^^
  File "C:\Users\SINCHAS\AppData\Local\Programs\Python\Python312\Lib\site-packages\uvicorn\lifespan\on.py", line 139, in receive
    return await self.receive_queue.get()
           ^^^^^^^^^^^^^^^^^^^^^^^^^^^^^^
  File "C:\Users\SINCHAS\AppData\Local\Programs\Python\Python312\Lib\asyncio\queues.py", line 158, in get
    await getter
asyncio.exceptions.CancelledError

19-Jun-25 10:05:57 - INFO - server.py - Started server process [27708]
19-Jun-25 10:05:57 - INFO - on.py - Waiting for application startup.
19-Jun-25 10:05:57 - INFO - on.py - Application startup complete.
19-Jun-25 10:05:57 - INFO - server.py - Shutting down
19-Jun-25 10:05:57 - INFO - on.py - Waiting for application shutdown.
19-Jun-25 10:05:57 - INFO - on.py - Application shutdown complete.
19-Jun-25 10:05:57 - INFO - server.py - Finished server process [27708]
19-Jun-25 10:05:59 - INFO - server.py - Started server process [33596]
19-Jun-25 10:05:59 - INFO - on.py - Waiting for application startup.
19-Jun-25 10:05:59 - INFO - on.py - Application startup complete.
19-Jun-25 10:06:00 - INFO - server.py - Shutting down
19-Jun-25 10:06:00 - INFO - on.py - Waiting for application shutdown.
19-Jun-25 10:06:00 - INFO - on.py - Application shutdown complete.
19-Jun-25 10:06:00 - INFO - server.py - Finished server process [33596]
19-Jun-25 10:06:03 - INFO - server.py - Started server process [24528]
19-Jun-25 10:06:03 - INFO - on.py - Waiting for application startup.
19-Jun-25 10:06:03 - INFO - on.py - Application startup complete.
19-Jun-25 10:06:05 - INFO - httptools_impl.py - 127.0.0.1:58333 - "GET /audit/audit-fields HTTP/1.1" 200
19-Jun-25 10:06:48 - INFO - server.py - Shutting down
19-Jun-25 10:06:48 - INFO - on.py - Waiting for application shutdown.
19-Jun-25 10:06:48 - INFO - on.py - Application shutdown complete.
19-Jun-25 10:06:48 - INFO - server.py - Finished server process [24528]
19-Jun-25 10:06:51 - INFO - server.py - Started server process [26336]
19-Jun-25 10:06:51 - INFO - on.py - Waiting for application startup.
19-Jun-25 10:06:51 - INFO - on.py - Application startup complete.
19-Jun-25 10:06:51 - INFO - server.py - Shutting down
19-Jun-25 10:06:51 - INFO - on.py - Waiting for application shutdown.
19-Jun-25 10:06:51 - INFO - on.py - Application shutdown complete.
19-Jun-25 10:06:51 - INFO - server.py - Finished server process [26336]
19-Jun-25 10:06:55 - INFO - server.py - Started server process [20144]
19-Jun-25 10:06:55 - INFO - on.py - Waiting for application startup.
19-Jun-25 10:06:55 - INFO - on.py - Application startup complete.
19-Jun-25 11:43:30 - INFO - httptools_impl.py - 127.0.0.1:55024 - "GET /audit/audit-fields HTTP/1.1" 200
19-Jun-25 11:44:22 - INFO - httptools_impl.py - 127.0.0.1:55086 - "GET /audit/audit-fields HTTP/1.1" 200
19-Jun-25 11:44:28 - INFO - httptools_impl.py - 127.0.0.1:55093 - "GET /audit/audit-tables HTTP/1.1" 200
19-Jun-25 11:44:44 - INFO - httptools_impl.py - 127.0.0.1:55130 - "POST /audit/add-audit HTTP/1.1" 200
19-Jun-25 11:46:37 - INFO - httptools_impl.py - 127.0.0.1:55306 - "GET /audit/audit-fields HTTP/1.1" 500
19-Jun-25 11:46:37 - ERROR - httptools_impl.py - Exception in ASGI application
  + Exception Group Traceback (most recent call last):
  |   File "C:\Users\SINCHAS\AppData\Local\Programs\Python\Python312\Lib\site-packages\uvicorn\protocols\http\httptools_impl.py", line 435, in run_asgi
  |     result = await app(  # type: ignore[func-returns-value]
  |              ^^^^^^^^^^^^^^^^^^^^^^^^^^^^^^^^^^^^^^^^^^^^^^
  |   File "C:\Users\SINCHAS\AppData\Local\Programs\Python\Python312\Lib\site-packages\uvicorn\middleware\proxy_headers.py", line 78, in __call__
  |     return await self.app(scope, receive, send)
  |            ^^^^^^^^^^^^^^^^^^^^^^^^^^^^^^^^^^^^
  |   File "C:\Users\SINCHAS\AppData\Local\Programs\Python\Python312\Lib\site-packages\uvicorn\middleware\message_logger.py", line 86, in __call__
  |     raise exc from None
  |   File "C:\Users\SINCHAS\AppData\Local\Programs\Python\Python312\Lib\site-packages\uvicorn\middleware\message_logger.py", line 82, in __call__
  |     await self.app(scope, inner_receive, inner_send)
  |   File "C:\Users\SINCHAS\AppData\Local\Programs\Python\Python312\Lib\site-packages\fastapi\applications.py", line 276, in __call__
  |     await super().__call__(scope, receive, send)
  |   File "C:\Users\SINCHAS\AppData\Local\Programs\Python\Python312\Lib\site-packages\starlette\applications.py", line 122, in __call__
  |     await self.middleware_stack(scope, receive, send)
  |   File "C:\Users\SINCHAS\AppData\Local\Programs\Python\Python312\Lib\site-packages\starlette\middleware\errors.py", line 184, in __call__
  |     raise exc
  |   File "C:\Users\SINCHAS\AppData\Local\Programs\Python\Python312\Lib\site-packages\starlette\middleware\errors.py", line 162, in __call__
  |     await self.app(scope, receive, _send)
  |   File "C:\Users\SINCHAS\AppData\Local\Programs\Python\Python312\Lib\site-packages\starlette\middleware\cors.py", line 84, in __call__
  |     await self.app(scope, receive, send)
  |   File "C:\Users\SINCHAS\AppData\Local\Programs\Python\Python312\Lib\site-packages\starlette\middleware\base.py", line 106, in __call__
  |     async with anyio.create_task_group() as task_group:
  |   File "C:\Users\SINCHAS\AppData\Local\Programs\Python\Python312\Lib\site-packages\anyio\_backends\_asyncio.py", line 678, in __aexit__
  |     raise BaseExceptionGroup(
  | ExceptionGroup: unhandled errors in a TaskGroup (1 sub-exception)
  +-+---------------- 1 ----------------
    | Traceback (most recent call last):
    |   File "C:\Users\SINCHAS\AppData\Local\Programs\Python\Python312\Lib\site-packages\sqlalchemy\engine\base.py", line 1963, in _exec_single_context
    |     self.dialect.do_execute(
    |   File "C:\Users\SINCHAS\AppData\Local\Programs\Python\Python312\Lib\site-packages\sqlalchemy\engine\default.py", line 920, in do_execute
    |     cursor.execute(statement, parameters)
    | psycopg2.errors.UndefinedColumn: column "akbeginndatum" does not exist
    | LINE 1: SELECT  id, pv_person_master_id, pers_nr, ak_nr, akBeginndat...
    |                                                          ^
    | HINT:  Perhaps you meant to reference the column "au_pv_ak.akBeginndatum".
    | 
    | 
    | The above exception was the direct cause of the following exception:
    | 
    | Traceback (most recent call last):
    |   File "C:\Users\SINCHAS\AppData\Local\Programs\Python\Python312\Lib\site-packages\starlette\middleware\base.py", line 108, in __call__
    |     response = await self.dispatch_func(request, call_next)
    |                ^^^^^^^^^^^^^^^^^^^^^^^^^^^^^^^^^^^^^^^^^^^^
    |   File "C:\Users\SINCHAS\Documents\GitHub\eProvision\backend\src\main.py", line 34, in dispatch
    |     response = await call_next(request)
    |                ^^^^^^^^^^^^^^^^^^^^^^^^
    |   File "C:\Users\SINCHAS\AppData\Local\Programs\Python\Python312\Lib\site-packages\starlette\middleware\base.py", line 84, in call_next
    |     raise app_exc
    |   File "C:\Users\SINCHAS\AppData\Local\Programs\Python\Python312\Lib\site-packages\starlette\middleware\base.py", line 70, in coro
    |     await self.app(scope, receive_or_disconnect, send_no_error)
    |   File "C:\Users\SINCHAS\AppData\Local\Programs\Python\Python312\Lib\site-packages\starlette\middleware\exceptions.py", line 79, in __call__
    |     raise exc
    |   File "C:\Users\SINCHAS\AppData\Local\Programs\Python\Python312\Lib\site-packages\starlette\middleware\exceptions.py", line 68, in __call__
    |     await self.app(scope, receive, sender)
    |   File "C:\Users\SINCHAS\AppData\Local\Programs\Python\Python312\Lib\site-packages\fastapi\middleware\asyncexitstack.py", line 21, in __call__
    |     raise e
    |   File "C:\Users\SINCHAS\AppData\Local\Programs\Python\Python312\Lib\site-packages\fastapi\middleware\asyncexitstack.py", line 18, in __call__
    |     await self.app(scope, receive, send)
    |   File "C:\Users\SINCHAS\AppData\Local\Programs\Python\Python312\Lib\site-packages\starlette\routing.py", line 718, in __call__
    |     await route.handle(scope, receive, send)
    |   File "C:\Users\SINCHAS\AppData\Local\Programs\Python\Python312\Lib\site-packages\starlette\routing.py", line 276, in handle
    |     await self.app(scope, receive, send)
    |   File "C:\Users\SINCHAS\AppData\Local\Programs\Python\Python312\Lib\site-packages\starlette\routing.py", line 66, in app
    |     response = await func(request)
    |                ^^^^^^^^^^^^^^^^^^^
    |   File "C:\Users\SINCHAS\AppData\Local\Programs\Python\Python312\Lib\site-packages\fastapi\routing.py", line 237, in app
    |     raw_response = await run_endpoint_function(
    |                    ^^^^^^^^^^^^^^^^^^^^^^^^^^^^
    |   File "C:\Users\SINCHAS\AppData\Local\Programs\Python\Python312\Lib\site-packages\fastapi\routing.py", line 163, in run_endpoint_function
    |     return await dependant.call(**values)
    |            ^^^^^^^^^^^^^^^^^^^^^^^^^^^^^^
    |   File "C:\Users\SINCHAS\Documents\GitHub\eProvision\backend\src\routers\audit_setup.py", line 17, in get_columns
    |     return get_column_data(tablename ,db)
    |            ^^^^^^^^^^^^^^^^^^^^^^^^^^^^^^
    |   File "C:\Users\SINCHAS\Documents\GitHub\eProvision\backend\src\modules\audit_setup\audit_setup.py", line 62, in get_column_data
    |     data = db.execute(text("SELECT {} FROM eprov.{} order by audit_stamp desc limit 100"
    |            ^^^^^^^^^^^^^^^^^^^^^^^^^^^^^^^^^^^^^^^^^^^^^^^^^^^^^^^^^^^^^^^^^^^^^^^^^^^^^
    |   File "C:\Users\SINCHAS\AppData\Local\Programs\Python\Python312\Lib\site-packages\sqlalchemy\orm\session.py", line 2232, in execute
    |     return self._execute_internal(
    |            ^^^^^^^^^^^^^^^^^^^^^^^
    |   File "C:\Users\SINCHAS\AppData\Local\Programs\Python\Python312\Lib\site-packages\sqlalchemy\orm\session.py", line 2136, in _execute_internal
    |     result = conn.execute(
    |              ^^^^^^^^^^^^^
    |   File "C:\Users\SINCHAS\AppData\Local\Programs\Python\Python312\Lib\site-packages\sqlalchemy\engine\base.py", line 1413, in execute
    |     return meth(
    |            ^^^^^
    |   File "C:\Users\SINCHAS\AppData\Local\Programs\Python\Python312\Lib\site-packages\sqlalchemy\sql\elements.py", line 483, in _execute_on_connection
    |     return connection._execute_clauseelement(
    |            ^^^^^^^^^^^^^^^^^^^^^^^^^^^^^^^^^^
    |   File "C:\Users\SINCHAS\AppData\Local\Programs\Python\Python312\Lib\site-packages\sqlalchemy\engine\base.py", line 1637, in _execute_clauseelement
    |     ret = self._execute_context(
    |           ^^^^^^^^^^^^^^^^^^^^^^
    |   File "C:\Users\SINCHAS\AppData\Local\Programs\Python\Python312\Lib\site-packages\sqlalchemy\engine\base.py", line 1841, in _execute_context
    |     return self._exec_single_context(
    |            ^^^^^^^^^^^^^^^^^^^^^^^^^^
    |   File "C:\Users\SINCHAS\AppData\Local\Programs\Python\Python312\Lib\site-packages\sqlalchemy\engine\base.py", line 1982, in _exec_single_context
    |     self._handle_dbapi_exception(
    |   File "C:\Users\SINCHAS\AppData\Local\Programs\Python\Python312\Lib\site-packages\sqlalchemy\engine\base.py", line 2339, in _handle_dbapi_exception
    |     raise sqlalchemy_exception.with_traceback(exc_info[2]) from e
    |   File "C:\Users\SINCHAS\AppData\Local\Programs\Python\Python312\Lib\site-packages\sqlalchemy\engine\base.py", line 1963, in _exec_single_context
    |     self.dialect.do_execute(
    |   File "C:\Users\SINCHAS\AppData\Local\Programs\Python\Python312\Lib\site-packages\sqlalchemy\engine\default.py", line 920, in do_execute
    |     cursor.execute(statement, parameters)
    | sqlalchemy.exc.ProgrammingError: (psycopg2.errors.UndefinedColumn) column "akbeginndatum" does not exist
    | LINE 1: SELECT  id, pv_person_master_id, pers_nr, ak_nr, akBeginndat...
    |                                                          ^
    | HINT:  Perhaps you meant to reference the column "au_pv_ak.akBeginndatum".
    | 
    | [SQL: SELECT  id, pv_person_master_id, pers_nr, ak_nr, akBeginndatum, akEnddatum, createdAt, updatedAt, audit_oprid, audit_stamp, audit_actn FROM eprov.au_pv_ak order by audit_stamp desc limit 100]
    | (Background on this error at: https://sqlalche.me/e/20/f405)
    +------------------------------------
19-Jun-25 11:47:50 - INFO - httptools_impl.py - 127.0.0.1:55377 - "GET /audit/audit-fields HTTP/1.1" 500
19-Jun-25 11:47:50 - ERROR - httptools_impl.py - Exception in ASGI application
  + Exception Group Traceback (most recent call last):
  |   File "C:\Users\SINCHAS\AppData\Local\Programs\Python\Python312\Lib\site-packages\uvicorn\protocols\http\httptools_impl.py", line 435, in run_asgi
  |     result = await app(  # type: ignore[func-returns-value]
  |              ^^^^^^^^^^^^^^^^^^^^^^^^^^^^^^^^^^^^^^^^^^^^^^
  |   File "C:\Users\SINCHAS\AppData\Local\Programs\Python\Python312\Lib\site-packages\uvicorn\middleware\proxy_headers.py", line 78, in __call__
  |     return await self.app(scope, receive, send)
  |            ^^^^^^^^^^^^^^^^^^^^^^^^^^^^^^^^^^^^
  |   File "C:\Users\SINCHAS\AppData\Local\Programs\Python\Python312\Lib\site-packages\uvicorn\middleware\message_logger.py", line 86, in __call__
  |     raise exc from None
  |   File "C:\Users\SINCHAS\AppData\Local\Programs\Python\Python312\Lib\site-packages\uvicorn\middleware\message_logger.py", line 82, in __call__
  |     await self.app(scope, inner_receive, inner_send)
  |   File "C:\Users\SINCHAS\AppData\Local\Programs\Python\Python312\Lib\site-packages\fastapi\applications.py", line 276, in __call__
  |     await super().__call__(scope, receive, send)
  |   File "C:\Users\SINCHAS\AppData\Local\Programs\Python\Python312\Lib\site-packages\starlette\applications.py", line 122, in __call__
  |     await self.middleware_stack(scope, receive, send)
  |   File "C:\Users\SINCHAS\AppData\Local\Programs\Python\Python312\Lib\site-packages\starlette\middleware\errors.py", line 184, in __call__
  |     raise exc
  |   File "C:\Users\SINCHAS\AppData\Local\Programs\Python\Python312\Lib\site-packages\starlette\middleware\errors.py", line 162, in __call__
  |     await self.app(scope, receive, _send)
  |   File "C:\Users\SINCHAS\AppData\Local\Programs\Python\Python312\Lib\site-packages\starlette\middleware\cors.py", line 84, in __call__
  |     await self.app(scope, receive, send)
  |   File "C:\Users\SINCHAS\AppData\Local\Programs\Python\Python312\Lib\site-packages\starlette\middleware\base.py", line 106, in __call__
  |     async with anyio.create_task_group() as task_group:
  |   File "C:\Users\SINCHAS\AppData\Local\Programs\Python\Python312\Lib\site-packages\anyio\_backends\_asyncio.py", line 678, in __aexit__
  |     raise BaseExceptionGroup(
  | ExceptionGroup: unhandled errors in a TaskGroup (1 sub-exception)
  +-+---------------- 1 ----------------
    | Traceback (most recent call last):
    |   File "C:\Users\SINCHAS\AppData\Local\Programs\Python\Python312\Lib\site-packages\starlette\middleware\base.py", line 108, in __call__
    |     response = await self.dispatch_func(request, call_next)
    |                ^^^^^^^^^^^^^^^^^^^^^^^^^^^^^^^^^^^^^^^^^^^^
    |   File "C:\Users\SINCHAS\Documents\GitHub\eProvision\backend\src\main.py", line 34, in dispatch
    |     response = await call_next(request)
    |                ^^^^^^^^^^^^^^^^^^^^^^^^
    |   File "C:\Users\SINCHAS\AppData\Local\Programs\Python\Python312\Lib\site-packages\starlette\middleware\base.py", line 84, in call_next
    |     raise app_exc
    |   File "C:\Users\SINCHAS\AppData\Local\Programs\Python\Python312\Lib\site-packages\starlette\middleware\base.py", line 70, in coro
    |     await self.app(scope, receive_or_disconnect, send_no_error)
    |   File "C:\Users\SINCHAS\AppData\Local\Programs\Python\Python312\Lib\site-packages\starlette\middleware\exceptions.py", line 79, in __call__
    |     raise exc
    |   File "C:\Users\SINCHAS\AppData\Local\Programs\Python\Python312\Lib\site-packages\starlette\middleware\exceptions.py", line 68, in __call__
    |     await self.app(scope, receive, sender)
    |   File "C:\Users\SINCHAS\AppData\Local\Programs\Python\Python312\Lib\site-packages\fastapi\middleware\asyncexitstack.py", line 21, in __call__
    |     raise e
    |   File "C:\Users\SINCHAS\AppData\Local\Programs\Python\Python312\Lib\site-packages\fastapi\middleware\asyncexitstack.py", line 18, in __call__
    |     await self.app(scope, receive, send)
    |   File "C:\Users\SINCHAS\AppData\Local\Programs\Python\Python312\Lib\site-packages\starlette\routing.py", line 718, in __call__
    |     await route.handle(scope, receive, send)
    |   File "C:\Users\SINCHAS\AppData\Local\Programs\Python\Python312\Lib\site-packages\starlette\routing.py", line 276, in handle
    |     await self.app(scope, receive, send)
    |   File "C:\Users\SINCHAS\AppData\Local\Programs\Python\Python312\Lib\site-packages\starlette\routing.py", line 66, in app
    |     response = await func(request)
    |                ^^^^^^^^^^^^^^^^^^^
    |   File "C:\Users\SINCHAS\AppData\Local\Programs\Python\Python312\Lib\site-packages\fastapi\routing.py", line 237, in app
    |     raw_response = await run_endpoint_function(
    |                    ^^^^^^^^^^^^^^^^^^^^^^^^^^^^
    |   File "C:\Users\SINCHAS\AppData\Local\Programs\Python\Python312\Lib\site-packages\fastapi\routing.py", line 163, in run_endpoint_function
    |     return await dependant.call(**values)
    |            ^^^^^^^^^^^^^^^^^^^^^^^^^^^^^^
    |   File "C:\Users\SINCHAS\Documents\GitHub\eProvision\backend\src\routers\audit_setup.py", line 17, in get_columns
    |     return get_column_data(tablename ,db)
    |            ^^^^^^^^^^^^^^^^^^^^^^^^^^^^^^
    |   File "C:\Users\SINCHAS\Documents\GitHub\eProvision\backend\src\modules\audit_setup\audit_setup.py", line 53, in get_column_data
    |     for column_name in inspector.get_columns(audit_table, schema='eprov'):
    |                        ^^^^^^^^^^^^^^^^^^^^^^^^^^^^^^^^^^^^^^^^^^^^^^^^^^
    |   File "C:\Users\SINCHAS\AppData\Local\Programs\Python\Python312\Lib\site-packages\sqlalchemy\engine\reflection.py", line 860, in get_columns
    |     col_defs = self.dialect.get_columns(
    |                ^^^^^^^^^^^^^^^^^^^^^^^^^
    |   File "<string>", line 2, in get_columns
    |   File "C:\Users\SINCHAS\AppData\Local\Programs\Python\Python312\Lib\site-packages\sqlalchemy\engine\reflection.py", line 97, in cache
    |     ret = fn(self, con, *args, **kw)
    |           ^^^^^^^^^^^^^^^^^^^^^^^^^^
    |   File "C:\Users\SINCHAS\AppData\Local\Programs\Python\Python312\Lib\site-packages\sqlalchemy\dialects\postgresql\base.py", line 3361, in get_columns
    |     return self._value_or_raise(data, table_name, schema)
    |            ^^^^^^^^^^^^^^^^^^^^^^^^^^^^^^^^^^^^^^^^^^^^^^
    |   File "C:\Users\SINCHAS\AppData\Local\Programs\Python\Python312\Lib\site-packages\sqlalchemy\dialects\postgresql\base.py", line 3329, in _value_or_raise
    |     raise exc.NoSuchTableError(
    | sqlalchemy.exc.NoSuchTableError: eprov.au_pv_abr_erg
    +------------------------------------
19-Jun-25 11:48:01 - INFO - httptools_impl.py - 127.0.0.1:55401 - "GET /audit/audit-tables HTTP/1.1" 200
19-Jun-25 11:48:11 - INFO - httptools_impl.py - 127.0.0.1:55416 - "GET /audit/audit-tables HTTP/1.1" 200
19-Jun-25 11:48:16 - INFO - httptools_impl.py - 127.0.0.1:55416 - "GET /audit/audit-fields HTTP/1.1" 200
19-Jun-25 11:48:24 - INFO - httptools_impl.py - 127.0.0.1:55432 - "GET /audit/audit-tables HTTP/1.1" 200
19-Jun-25 11:48:31 - INFO - httptools_impl.py - 127.0.0.1:55447 - "POST /audit/add-audit HTTP/1.1" 200
19-Jun-25 11:48:36 - INFO - httptools_impl.py - 127.0.0.1:55459 - "GET /audit/audit-fields HTTP/1.1" 200
